<?xml version="1.0" encoding="utf-8"?>

<!-- ================= SYMBOLIC URDF ================= -->
<!-- indefinite variables are written in #|this_form|# -->

<robot name="kinovo"
       xmlns:xacro="http://www.ros.org/wiki/xacro">

  <!-- import macros -->
  <xacro:include filename="$(find urdf_estimation_with_imus)/imu_module/krs6104_imu.xacro" />
  <xacro:include filename="$(find urdf_estimation_with_imus)/imu_module/krs3304_imu.xacro" />

  <!-- macro for generator for IMUs' reference frames -->
  <xacro:macro name="joint_with_imu_link"
               params="joint_name parent_link child_link xyz rpy">

    <!-- dummy joint for parent position to avoid rotating with child link -->
    <joint name="${parent_link}_to_${joint_name}_connector" type="fixed">
      <origin xyz="${xyz}" rpy="${rpy}" />
      <parent link="${parent_link}" />
      <child link="${joint_name}__link__" />
    </joint>

    <!-- dummy link for parent IMU -->
    <link name="${joint_name}__link__">
    </link>

    <!-- original revolute joint -->
    <joint name="${joint_name}" type="revolute">
      <origin xyz="0 0 0" rpy="0 0 0" /> <!-- must be 0 0 0 / 0 0 0 -->
      <parent link="${joint_name}__link__" />
      <child link="${child_link}" />
      <axis xyz="0 0 1" />
      <limit lower="-3.14" upper="3.14" effort="100" velocity="1.57" />
    </joint>

  </xacro:macro>

  <!-- macro for generator for IMUs' reference frames -->
  <xacro:macro name="joint_with_imu_link_symbolic"
               params="joint_name parent_link child_link">
    <xacro:joint_with_imu_link
            joint_name="${joint_name}"
            parent_link="${parent_link}" child_link="${child_link}"
            xyz="#|${joint_name}_xyz|#" rpy="#|${joint_name}_rpy|#" />
  </xacro:macro>

  <!-- main part -->
  <link name="world">
  </link>

  <joint name="world_fixed_joint" type="fixed">
    <origin xyz="0 0 0" rpy="0 0 0" />
    <parent link="world" />
    <child link="base_link" />
  </joint>

  <!-- links -->
  <link name="base_link">
  </link>
  <link name="link0">
  </link>

  <!-- joints -->
  <xacro:joint_with_imu_link
            joint_name="joint0"
            parent_link="base_link" child_link="link0"
            xyz="0 0 0.045" rpy="3.14159265 0 0" />

  <xacro:krs6104_imumodule joint_name="joint0" child_link="link0" />

</robot>