<?xml version="1.0" encoding="utf-8"?>

<!-- ================= SYMBOLIC URDF ================= -->
<!-- indefinite variables are written in #|this_form|# -->

<robot name="two_imus"
       xmlns:xacro="http://www.ros.org/wiki/xacro">

  <!-- main part -->
  <link name="world">
  </link>

  <joint name="world_fixed_joint" type="fixed">
    <origin xyz="0 0 0" rpy="0 0 0" />
    <parent link="world" />
    <child link="imu0" />
  </joint>

  <!-- links -->
  <link name="imu0">
  </link>
  <link name="imu1">
  </link>

  <!-- joint with IMUs -->
  <joint name="imu_virtual_joint" type="revolute">
    <origin xyz="#|imu_relpos|#" rpy="#|imu_relrpy|#" />
    <parent link="imu0" />
    <child link="imu1" />
    <axis xyz="0 0 1" />
    <limit lower="-3.14" upper="3.14" effort="100" velocity="1.57" />
  </joint>

</robot>